<?xml version="1.0" encoding="UTF-8"?>
<testng-results retried="1" ignored="0" total="6" passed="2" failed="2" skipped="1">
  <reporter-output>
  </reporter-output>
  <suite started-at="2025-05-01T23:28:21 IST" name="Suite" finished-at="2025-05-01T23:29:01 IST" duration-ms="40036">
    <groups>
      <group name="E2E Testing">
        <method signature="SubmitOrderTest.submitOrder(java.util.HashMap)[pri:0, instance:Learnings.Tests.SubmitOrderTest@60f00693]" name="submitOrder" class="Learnings.Tests.SubmitOrderTest"/>
      </group> <!-- E2E Testing -->
    </groups>
    <test started-at="2025-05-01T23:28:21 IST" name="Error Validations" finished-at="2025-05-01T23:28:42 IST" duration-ms="20549">
      <class name="Learnings.Tests.ErrorValidations">
        <test-method is-config="true" signature="lounchApplication()[pri:0, instance:Learnings.Tests.ErrorValidations@31ea9581]" started-at="2025-05-01T23:28:21 IST" name="lounchApplication" finished-at="2025-05-01T23:28:26 IST" duration-ms="4971" status="PASS">
          <reporter-output>
          </reporter-output>
        </test-method> <!-- lounchApplication -->
        <test-method signature="ErrorValidationsTest()[pri:0, instance:Learnings.Tests.ErrorValidations@31ea9581]" started-at="2025-05-01T23:28:26 IST" name="ErrorValidationsTest" finished-at="2025-05-01T23:28:29 IST" duration-ms="2629" status="PASS">
          <reporter-output>
          </reporter-output>
        </test-method> <!-- ErrorValidationsTest -->
        <test-method is-config="true" signature="tearDown()[pri:0, instance:Learnings.Tests.ErrorValidations@31ea9581]" started-at="2025-05-01T23:28:29 IST" name="tearDown" finished-at="2025-05-01T23:28:29 IST" duration-ms="231" status="PASS">
          <reporter-output>
          </reporter-output>
        </test-method> <!-- tearDown -->
        <test-method is-config="true" signature="lounchApplication()[pri:0, instance:Learnings.Tests.ErrorValidations@31ea9581]" started-at="2025-05-01T23:28:29 IST" name="lounchApplication" finished-at="2025-05-01T23:28:31 IST" duration-ms="1555" status="PASS">
          <reporter-output>
          </reporter-output>
        </test-method> <!-- lounchApplication -->
        <test-method retried="true" signature="productValidationCheck()[pri:0, instance:Learnings.Tests.ErrorValidations@31ea9581]" started-at="2025-05-01T23:28:31 IST" name="productValidationCheck" finished-at="2025-05-01T23:28:35 IST" duration-ms="4304" status="SKIP">
          <exception class="java.lang.AssertionError">
            <message>
              <![CDATA[expected [true] but found [false]]]>
            </message>
            <full-stacktrace>
              <![CDATA[java.lang.AssertionError: expected [true] but found [false]
at org.testng.Assert.fail(Assert.java:110)
at org.testng.Assert.failNotEquals(Assert.java:1577)
at org.testng.Assert.assertTrue(Assert.java:56)
at org.testng.Assert.assertTrue(Assert.java:66)
at Learnings.Tests.ErrorValidations.productValidationCheck(ErrorValidations.java:33)
at java.base/jdk.internal.reflect.DirectMethodHandleAccessor.invoke(DirectMethodHandleAccessor.java:103)
at java.base/java.lang.reflect.Method.invoke(Method.java:580)
at org.testng.internal.invokers.MethodInvocationHelper.invokeMethod(MethodInvocationHelper.java:139)
at org.testng.internal.invokers.TestInvoker.invokeMethod(TestInvoker.java:677)
at org.testng.internal.invokers.TestInvoker.invokeTestMethod(TestInvoker.java:221)
at org.testng.internal.invokers.MethodRunner.runInSequence(MethodRunner.java:50)
at org.testng.internal.invokers.TestInvoker$MethodInvocationAgent.invoke(TestInvoker.java:969)
at org.testng.internal.invokers.TestInvoker.invokeTestMethods(TestInvoker.java:194)
at org.testng.internal.invokers.TestMethodWorker.invokeTestMethods(TestMethodWorker.java:148)
at org.testng.internal.invokers.TestMethodWorker.run(TestMethodWorker.java:128)
at java.base/java.util.ArrayList.forEach(ArrayList.java:1596)
at org.testng.TestRunner.privateRun(TestRunner.java:829)
at org.testng.TestRunner.run(TestRunner.java:602)
at org.testng.SuiteRunner.runTest(SuiteRunner.java:437)
at org.testng.SuiteRunner.runSequentially(SuiteRunner.java:431)
at org.testng.SuiteRunner.privateRun(SuiteRunner.java:391)
at org.testng.SuiteRunner.run(SuiteRunner.java:330)
at org.testng.SuiteRunnerWorker.runSuite(SuiteRunnerWorker.java:52)
at org.testng.SuiteRunnerWorker.run(SuiteRunnerWorker.java:95)
at org.testng.TestNG.runSuitesSequentially(TestNG.java:1256)
at org.testng.TestNG.runSuitesLocally(TestNG.java:1176)
at org.testng.TestNG.runSuites(TestNG.java:1099)
at org.testng.TestNG.run(TestNG.java:1067)
at org.apache.maven.surefire.testng.TestNGExecutor.run(TestNGExecutor.java:308)
at org.apache.maven.surefire.testng.TestNGXmlTestSuite.execute(TestNGXmlTestSuite.java:71)
at org.apache.maven.surefire.testng.TestNGProvider.invoke(TestNGProvider.java:113)
at org.apache.maven.surefire.booter.ForkedBooter.runSuitesInProcess(ForkedBooter.java:385)
at org.apache.maven.surefire.booter.ForkedBooter.execute(ForkedBooter.java:162)
at org.apache.maven.surefire.booter.ForkedBooter.run(ForkedBooter.java:507)
at org.apache.maven.surefire.booter.ForkedBooter.main(ForkedBooter.java:495)
]]>
            </full-stacktrace>
          </exception> <!-- java.lang.AssertionError -->
          <reporter-output>
          </reporter-output>
        </test-method> <!-- productValidationCheck -->
        <test-method is-config="true" signature="tearDown()[pri:0, instance:Learnings.Tests.ErrorValidations@31ea9581]" started-at="2025-05-01T23:28:35 IST" name="tearDown" finished-at="2025-05-01T23:28:35 IST" duration-ms="105" status="PASS">
          <reporter-output>
          </reporter-output>
        </test-method> <!-- tearDown -->
        <test-method is-config="true" signature="lounchApplication()[pri:0, instance:Learnings.Tests.ErrorValidations@31ea9581]" started-at="2025-05-01T23:28:35 IST" name="lounchApplication" finished-at="2025-05-01T23:28:38 IST" duration-ms="2847" status="PASS">
          <reporter-output>
          </reporter-output>
        </test-method> <!-- lounchApplication -->
        <test-method signature="productValidationCheck()[pri:0, instance:Learnings.Tests.ErrorValidations@31ea9581]" started-at="2025-05-01T23:28:38 IST" name="productValidationCheck" finished-at="2025-05-01T23:28:41 IST" duration-ms="2530" status="FAIL">
          <exception class="java.lang.AssertionError">
            <message>
              <![CDATA[expected [true] but found [false]]]>
            </message>
            <full-stacktrace>
              <![CDATA[java.lang.AssertionError: expected [true] but found [false]
at org.testng.Assert.fail(Assert.java:110)
at org.testng.Assert.failNotEquals(Assert.java:1577)
at org.testng.Assert.assertTrue(Assert.java:56)
at org.testng.Assert.assertTrue(Assert.java:66)
at Learnings.Tests.ErrorValidations.productValidationCheck(ErrorValidations.java:33)
at java.base/jdk.internal.reflect.DirectMethodHandleAccessor.invoke(DirectMethodHandleAccessor.java:103)
at java.base/java.lang.reflect.Method.invoke(Method.java:580)
at org.testng.internal.invokers.MethodInvocationHelper.invokeMethod(MethodInvocationHelper.java:139)
at org.testng.internal.invokers.TestInvoker.invokeMethod(TestInvoker.java:677)
at org.testng.internal.invokers.TestInvoker.retryFailed(TestInvoker.java:263)
at org.testng.internal.invokers.MethodRunner.runInSequence(MethodRunner.java:62)
at org.testng.internal.invokers.TestInvoker$MethodInvocationAgent.invoke(TestInvoker.java:969)
at org.testng.internal.invokers.TestInvoker.invokeTestMethods(TestInvoker.java:194)
at org.testng.internal.invokers.TestMethodWorker.invokeTestMethods(TestMethodWorker.java:148)
at org.testng.internal.invokers.TestMethodWorker.run(TestMethodWorker.java:128)
at java.base/java.util.ArrayList.forEach(ArrayList.java:1596)
at org.testng.TestRunner.privateRun(TestRunner.java:829)
at org.testng.TestRunner.run(TestRunner.java:602)
at org.testng.SuiteRunner.runTest(SuiteRunner.java:437)
at org.testng.SuiteRunner.runSequentially(SuiteRunner.java:431)
at org.testng.SuiteRunner.privateRun(SuiteRunner.java:391)
at org.testng.SuiteRunner.run(SuiteRunner.java:330)
at org.testng.SuiteRunnerWorker.runSuite(SuiteRunnerWorker.java:52)
at org.testng.SuiteRunnerWorker.run(SuiteRunnerWorker.java:95)
at org.testng.TestNG.runSuitesSequentially(TestNG.java:1256)
at org.testng.TestNG.runSuitesLocally(TestNG.java:1176)
at org.testng.TestNG.runSuites(TestNG.java:1099)
at org.testng.TestNG.run(TestNG.java:1067)
at org.apache.maven.surefire.testng.TestNGExecutor.run(TestNGExecutor.java:308)
at org.apache.maven.surefire.testng.TestNGXmlTestSuite.execute(TestNGXmlTestSuite.java:71)
at org.apache.maven.surefire.testng.TestNGProvider.invoke(TestNGProvider.java:113)
at org.apache.maven.surefire.booter.ForkedBooter.runSuitesInProcess(ForkedBooter.java:385)
at org.apache.maven.surefire.booter.ForkedBooter.execute(ForkedBooter.java:162)
at org.apache.maven.surefire.booter.ForkedBooter.run(ForkedBooter.java:507)
at org.apache.maven.surefire.booter.ForkedBooter.main(ForkedBooter.java:495)
]]>
            </full-stacktrace>
          </exception> <!-- java.lang.AssertionError -->
          <reporter-output>
          </reporter-output>
        </test-method> <!-- productValidationCheck -->
        <test-method is-config="true" signature="tearDown()[pri:0, instance:Learnings.Tests.ErrorValidations@31ea9581]" started-at="2025-05-01T23:28:42 IST" name="tearDown" finished-at="2025-05-01T23:28:42 IST" duration-ms="245" status="PASS">
          <reporter-output>
          </reporter-output>
        </test-method> <!-- tearDown -->
      </class> <!-- Learnings.Tests.ErrorValidations -->
    </test> <!-- Error Validations -->
    <test started-at="2025-05-01T23:28:42 IST" name="Tests" finished-at="2025-05-01T23:29:01 IST" duration-ms="19018">
      <class name="Learnings.Tests.SubmitOrderTest">
        <test-method is-config="true" signature="lounchApplication()[pri:0, instance:Learnings.Tests.SubmitOrderTest@60f00693]" started-at="2025-05-01T23:28:43 IST" name="lounchApplication" finished-at="2025-05-01T23:28:47 IST" duration-ms="3736" status="PASS">
          <reporter-output>
          </reporter-output>
        </test-method> <!-- lounchApplication -->
        <test-method signature="submitOrder(java.util.HashMap)[pri:0, instance:Learnings.Tests.SubmitOrderTest@60f00693]" started-at="2025-05-01T23:28:47 IST" name="submitOrder" data-provider="getData" finished-at="2025-05-01T23:28:49 IST" duration-ms="2577" status="FAIL">
          <params>
            <param index="0">
              <value>
                <![CDATA[{passWord=!123weSDF, userName=nikhil1997@gmail.com, productName=ADIDAS ORIGINAL}]]>
              </value>
            </param>
          </params>
          <exception class="java.lang.AssertionError">
            <message>
              <![CDATA[expected [true] but found [false]]]>
            </message>
            <full-stacktrace>
              <![CDATA[java.lang.AssertionError: expected [true] but found [false]
at org.testng.Assert.fail(Assert.java:110)
at org.testng.Assert.failNotEquals(Assert.java:1577)
at org.testng.Assert.assertTrue(Assert.java:56)
at org.testng.Assert.assertTrue(Assert.java:66)
at Learnings.Tests.SubmitOrderTest.submitOrder(SubmitOrderTest.java:66)
at java.base/jdk.internal.reflect.DirectMethodHandleAccessor.invoke(DirectMethodHandleAccessor.java:103)
at java.base/java.lang.reflect.Method.invoke(Method.java:580)
at org.testng.internal.invokers.MethodInvocationHelper.invokeMethod(MethodInvocationHelper.java:139)
at org.testng.internal.invokers.TestInvoker.invokeMethod(TestInvoker.java:677)
at org.testng.internal.invokers.TestInvoker.invokeTestMethod(TestInvoker.java:221)
at org.testng.internal.invokers.MethodRunner.runInSequence(MethodRunner.java:50)
at org.testng.internal.invokers.TestInvoker$MethodInvocationAgent.invoke(TestInvoker.java:969)
at org.testng.internal.invokers.TestInvoker.invokeTestMethods(TestInvoker.java:194)
at org.testng.internal.invokers.TestMethodWorker.invokeTestMethods(TestMethodWorker.java:148)
at org.testng.internal.invokers.TestMethodWorker.run(TestMethodWorker.java:128)
at java.base/java.util.ArrayList.forEach(ArrayList.java:1596)
at org.testng.TestRunner.privateRun(TestRunner.java:829)
at org.testng.TestRunner.run(TestRunner.java:602)
at org.testng.SuiteRunner.runTest(SuiteRunner.java:437)
at org.testng.SuiteRunner.runSequentially(SuiteRunner.java:431)
at org.testng.SuiteRunner.privateRun(SuiteRunner.java:391)
at org.testng.SuiteRunner.run(SuiteRunner.java:330)
at org.testng.SuiteRunnerWorker.runSuite(SuiteRunnerWorker.java:52)
at org.testng.SuiteRunnerWorker.run(SuiteRunnerWorker.java:95)
at org.testng.TestNG.runSuitesSequentially(TestNG.java:1256)
at org.testng.TestNG.runSuitesLocally(TestNG.java:1176)
at org.testng.TestNG.runSuites(TestNG.java:1099)
at org.testng.TestNG.run(TestNG.java:1067)
at org.apache.maven.surefire.testng.TestNGExecutor.run(TestNGExecutor.java:308)
at org.apache.maven.surefire.testng.TestNGXmlTestSuite.execute(TestNGXmlTestSuite.java:71)
at org.apache.maven.surefire.testng.TestNGProvider.invoke(TestNGProvider.java:113)
at org.apache.maven.surefire.booter.ForkedBooter.runSuitesInProcess(ForkedBooter.java:385)
at org.apache.maven.surefire.booter.ForkedBooter.execute(ForkedBooter.java:162)
at org.apache.maven.surefire.booter.ForkedBooter.run(ForkedBooter.java:507)
at org.apache.maven.surefire.booter.ForkedBooter.main(ForkedBooter.java:495)
]]>
            </full-stacktrace>
          </exception> <!-- java.lang.AssertionError -->
          <reporter-output>
          </reporter-output>
        </test-method> <!-- submitOrder -->
        <test-method is-config="true" signature="tearDown()[pri:0, instance:Learnings.Tests.SubmitOrderTest@60f00693]" started-at="2025-05-01T23:28:50 IST" name="tearDown" finished-at="2025-05-01T23:28:50 IST" duration-ms="71" status="PASS">
          <reporter-output>
          </reporter-output>
        </test-method> <!-- tearDown -->
        <test-method is-config="true" signature="lounchApplication()[pri:0, instance:Learnings.Tests.SubmitOrderTest@60f00693]" started-at="2025-05-01T23:28:50 IST" name="lounchApplication" finished-at="2025-05-01T23:28:53 IST" duration-ms="2701" status="PASS">
          <reporter-output>
          </reporter-output>
        </test-method> <!-- lounchApplication -->
        <test-method signature="submitOrder(java.util.HashMap)[pri:0, instance:Learnings.Tests.SubmitOrderTest@60f00693]" started-at="2025-05-01T23:28:53 IST" name="submitOrder" data-provider="getData" finished-at="2025-05-01T23:29:01 IST" duration-ms="8466" status="PASS">
          <params>
            <param index="0">
              <value>
                <![CDATA[{passWord=#345rtFGH, userName=mayur1995@gmail.com, productName=IPHONE 13 PRO}]]>
              </value>
            </param>
          </params>
          <reporter-output>
          </reporter-output>
        </test-method> <!-- submitOrder -->
        <test-method is-config="true" signature="tearDown()[pri:0, instance:Learnings.Tests.SubmitOrderTest@60f00693]" started-at="2025-05-01T23:29:01 IST" name="tearDown" finished-at="2025-05-01T23:29:01 IST" duration-ms="106" status="PASS">
          <reporter-output>
          </reporter-output>
        </test-method> <!-- tearDown -->
        <test-method signature="MyOrders()[pri:0, instance:Learnings.Tests.SubmitOrderTest@60f00693]" started-at="2025-05-01T23:29:01 IST" name="MyOrders" finished-at="2025-05-01T23:29:01 IST" depends-on-methods="Learnings.Tests.SubmitOrderTest.submitOrder" duration-ms="0" status="SKIP">
          <exception class="java.lang.Throwable">
            <message>
              <![CDATA[Method Learnings.Tests.SubmitOrderTest.MyOrders() on instance Learnings.Tests.SubmitOrderTest@60f00693 depends on not successfully finished methods 
[Learnings.Tests.SubmitOrderTest.submitOrder() on instance Learnings.Tests.SubmitOrderTest@60f00693]]]>
            </message>
            <full-stacktrace>
              <![CDATA[java.lang.Throwable: Method Learnings.Tests.SubmitOrderTest.MyOrders() on instance Learnings.Tests.SubmitOrderTest@60f00693 depends on not successfully finished methods 
[Learnings.Tests.SubmitOrderTest.submitOrder() on instance Learnings.Tests.SubmitOrderTest@60f00693]
at org.testng.internal.invokers.TestInvoker.invokeTestMethods(TestInvoker.java:150)
at org.testng.internal.invokers.TestMethodWorker.invokeTestMethods(TestMethodWorker.java:148)
at org.testng.internal.invokers.TestMethodWorker.run(TestMethodWorker.java:128)
at java.base/java.util.ArrayList.forEach(ArrayList.java:1596)
at org.testng.TestRunner.privateRun(TestRunner.java:829)
at org.testng.TestRunner.run(TestRunner.java:602)
at org.testng.SuiteRunner.runTest(SuiteRunner.java:437)
at org.testng.SuiteRunner.runSequentially(SuiteRunner.java:431)
at org.testng.SuiteRunner.privateRun(SuiteRunner.java:391)
at org.testng.SuiteRunner.run(SuiteRunner.java:330)
at org.testng.SuiteRunnerWorker.runSuite(SuiteRunnerWorker.java:52)
at org.testng.SuiteRunnerWorker.run(SuiteRunnerWorker.java:95)
at org.testng.TestNG.runSuitesSequentially(TestNG.java:1256)
at org.testng.TestNG.runSuitesLocally(TestNG.java:1176)
at org.testng.TestNG.runSuites(TestNG.java:1099)
at org.testng.TestNG.run(TestNG.java:1067)
at org.apache.maven.surefire.testng.TestNGExecutor.run(TestNGExecutor.java:308)
at org.apache.maven.surefire.testng.TestNGXmlTestSuite.execute(TestNGXmlTestSuite.java:71)
at org.apache.maven.surefire.testng.TestNGProvider.invoke(TestNGProvider.java:113)
at org.apache.maven.surefire.booter.ForkedBooter.runSuitesInProcess(ForkedBooter.java:385)
at org.apache.maven.surefire.booter.ForkedBooter.execute(ForkedBooter.java:162)
at org.apache.maven.surefire.booter.ForkedBooter.run(ForkedBooter.java:507)
at org.apache.maven.surefire.booter.ForkedBooter.main(ForkedBooter.java:495)
]]>
            </full-stacktrace>
          </exception> <!-- java.lang.Throwable -->
          <reporter-output>
          </reporter-output>
        </test-method> <!-- MyOrders -->
      </class> <!-- Learnings.Tests.SubmitOrderTest -->
    </test> <!-- Tests -->
  </suite> <!-- Suite -->
</testng-results>
